<?xml version="1.0" ?>
<!-- =================================================================================== -->
<!-- |    This document was autogenerated by xacro from rgator_model.urdf              | -->
<!-- |    EDITING THIS FILE BY HAND IS NOT RECOMMENDED                                 | -->
<!-- =================================================================================== -->
<!-- This URDF was automatically created by SolidWorks to URDF Exporter! Originally created by Stephen Brawner (brawner@gmail.com) 
     Commit Version: 1.6.0-4-g7f85cfe  Build Version: 1.6.7995.38578
     For more information, please see http://wiki.ros.org/sw_urdf_exporter -->
<robot name="rgator_model" xmlns:xacro="http://www.ros.org/wiki/xacro">
    <xacro:include filename="$(find rgator_model)/urdf/rgator.gazebo" />
    <xacro:include filename="$(find rgator_model)/urdf/macros.xacro" />

    <xacro:arg name="velodyne_points" default="false"/>
    <xacro:arg name="laser_points" default="false"/>
    
    <xacro:property name="velodyne_points" value="$(arg velodyne_points)"/>
    <xacro:property name="laser_points" value="$(arg laser_points)"/>
    <xacro:include filename="$(find velodyne_description)/urdf/VLP-16.urdf.xacro"/>

    <link name="base_footprint"> 
        </link>

    <link name="base_link">
        <inertial>
        <origin rpy="0 0 0" xyz="-0.037681 0.0005416 0.38334"/>
        <mass value="1146.5"/>
        <!-- <inertia ixx="186.85" ixy="-0.0060656" ixz="-42.111" iyy="677.82" iyz="-0.002351" izz="717.22"/> -->
        <inertia
            ixx="205.702789313137"
            ixy="-0.20742120719075"
            ixz="-9.13771633467953"
            iyy="482.020173559149"
            iyz="0.0517191981605489"
            izz="482.316418870047" />
        </inertial>

        <visual>
        <origin rpy="0 0 0" xyz="0 0 0"/>
        <geometry>
            <mesh filename="package://rgator_model/meshes/base_link.STL"/>
        </geometry>
        <material name="">
            <color rgba="0.1451 0.24706 0 1"/>
        </material>
        </visual>
        <collision>
        <origin rpy="0 0 0" xyz="0 0 0"/>
        <geometry>
            <mesh filename="package://rgator_model/meshes/base_link.STL"/>
        </geometry>
        </collision>
    </link>

        <joint name="base_link" type="fixed">
            <origin xyz="0 0 0" rpy="0 0 0"/>
            <parent link="base_footprint"/>
            <child link="base_link"/>
        </joint>

    <!-- ***************************************** Wheel settings below ****************************************** -->

    <!-- Front left wheel -->
    <link name="left_steering_hinge_link">
        <inertial>
        <mass value="1"/>
        <origin xyz="0 0 0" rpy="0 0 0"/>
        <inertia ixx="0.004" ixy="0.0" ixz="0.0" iyy="0.004" iyz="0.0" izz="0.004"/>
        </inertial>
    </link>

    <joint name="left_steering_hinge_joint" type="revolute">
        <parent link="base_link"/>
        <child link="left_steering_hinge_link"/>
        <origin xyz="0.998679994403652 0.61 0.0899999999999999" rpy="0 0 0"/>    
        <axis xyz="0 0 1" />
        <limit lower="-0.61" upper="0.61" effort="1000" velocity="0.5"/>
    </joint>

    <link name="front_left_wheel_link">
        <inertial>
            <origin rpy="0 0 0" xyz="4.44089209850063E-16 -0.0223230092959477 0"/>
            <mass value="68.0202335873534"/>
            <!-- <inertia ixx="1.8451330504804" ixy="4.81369033677265E-19" ixz="8.04542333548677E-19" iyy="2.55906848679382" iyz="1.20230823572989E-16" izz="1.8451330504804"/>-->

            <inertia ixx="0.58631238" ixy="0.0" ixz="0.0" iyy="0.33552910" iyz="0.0" izz="0.33552910"/>
        </inertial>
        <visual>
        <origin rpy="0 0 0" xyz="0 0 0"/>
        <geometry>
            <mesh filename="package://rgator_model/meshes/front_left_wheel_link.STL"/>
        </geometry>
        <material name="">
            <color rgba="0.250980392156863 0.250980392156863 0.250980392156863 1"/>
        </material>
        </visual>
        <collision>
        <origin rpy="0 0 0" xyz="0 0 0"/>
        <geometry>
            <mesh filename="package://rgator_model/meshes/front_left_wheel_link.STL"/>
        </geometry>
        </collision>
    </link>
    <joint name="front_left_wheel_joint" type="continuous">
        <origin rpy="0 0 0" xyz="0 0 0"/>
        <parent link="left_steering_hinge_link"/>
        <child link="front_left_wheel_link"/>
        <axis xyz="0 1 0"/>
        <limit effort="1000" velocity="100.0"/>
    </joint>

    <!-- Front right wheel -->
    <link name="right_steering_hinge_link">
        <inertial>
        <mass value="1"/>
        <origin xyz="0 0 0" rpy="0 0 0"/>
        <inertia ixx="0.004" ixy="0.0" ixz="0.0" iyy="0.004" iyz="0.0" izz="0.004"/>
        </inertial>
    </link>

    <joint name="right_steering_hinge_joint" type="revolute">
        <parent link="base_link"/>
        <child link="right_steering_hinge_link"/>
        <origin xyz="0.998679994403652 -0.61 0.0899999999999999" rpy="0 0 0"/>
        <axis xyz="0 0 1" />
        <limit lower="-0.61" upper="0.61" effort="1000" velocity="0.5"/>
    </joint>

    <link name="front_right_wheel_link">
        <inertial>
        <origin rpy="0 0 0" xyz="0 0.0223230092959477 0"/>
        <mass value="68.0202335873534"/>
        <!-- <inertia ixx="1.8451330504804" ixy="-1.08723575624602E-17" ixz="-1.01659412021803E-16" iyy="2.55906848679382" iyz="9.13042816242676E-17" izz="1.8451330504804"/> -->
        <inertia ixx="0.58631238" ixy="0.0" ixz="0.0" iyy="0.33552910" iyz="0.0" izz="0.33552910"/>
        </inertial>
        <visual>
        <origin rpy="0 0 0" xyz="0 0 0"/>
        <geometry>
            <mesh filename="package://rgator_model/meshes/front_right_wheel_link.STL"/>
        </geometry>
        <material name="">
            <color rgba="0.250980392156863 0.250980392156863 0.250980392156863 1"/>
        </material>
        </visual>
        <collision>
        <origin rpy="0 0 0" xyz="0 0 0"/>
        <geometry>
            <mesh filename="package://rgator_model/meshes/front_right_wheel_link.STL"/>
        </geometry>
        </collision>
    </link>
    <joint name="front_right_wheel_joint" type="continuous">
        <origin rpy="0 0 0" xyz="0 0 0"/>
        <parent link="right_steering_hinge_link"/>
        <child link="front_right_wheel_link"/>
        <axis xyz="0 1 0"/>
        <limit effort="1000" velocity="100.0"/>
    </joint>

    <!-- Middle left wheel -->
    <link name="middle_left_wheel_link">
        <inertial>
        <origin rpy="0 0 0" xyz="0 -0.0223230092959477 0"/>
        <mass value="68.0202335873534"/>
        <!-- <inertia ixx="1.8451330504804" ixy="-5.93594276904364E-17" ixz="-3.57062680215511E-17" iyy="2.55906848679382" iyz="2.35917879413298E-16" izz="1.8451330504804"/> -->
        <inertia ixx="0.58631238" ixy="0.0" ixz="0.0" iyy="0.33552910" iyz="0.0" izz="0.33552910"/>
        </inertial>
        <visual>
        <origin rpy="0 0 0" xyz="0 0 0"/>
        <geometry>
            <mesh filename="package://rgator_model/meshes/middle_left_wheel_link.STL"/>
        </geometry>
        <material name="">
            <color rgba="0.250980392156863 0.250980392156863 0.250980392156863 1"/>
        </material>
        </visual>
        <collision>
        <origin rpy="0 0 0" xyz="0 0 0"/>
        <geometry>
            <mesh filename="package://rgator_model/meshes/middle_left_wheel_link.STL"/>
        </geometry>
        </collision>
    </link>
    <joint name="middle_left_wheel_joint" type="continuous">
        <origin rpy="0 0 0" xyz="-0.331320005596349 0.61 0.0900000000000012"/>
        <parent link="base_link"/>
        <child link="middle_left_wheel_link"/>
        <axis xyz="0 1 0"/>
        <limit effort="1000" velocity="100.0"/>
    </joint>

    <!-- Middle right wheel -->
    <link name="middle_right_wheel_link">
        <inertial>
        <origin rpy="0 0 0" xyz="0 0.0223230092959477 -4.44089209850063E-16"/>
        <mass value="68.0202335873534"/>
        <!-- <inertia ixx="1.8451330504804" ixy="-6.79305383740351E-17" ixz="2.72115687052549E-17" iyy="2.55906848679382" iyz="1.24089728291413E-16" izz="1.8451330504804"/> -->
        <inertia ixx="0.58631238" ixy="0.0" ixz="0.0" iyy="0.33552910" iyz="0.0" izz="0.33552910"/>
        </inertial>
        <visual>
        <origin rpy="0 0 0" xyz="0 0 0"/>
        <geometry>
            <mesh filename="package://rgator_model/meshes/middle_right_wheel_link.STL"/>
        </geometry>
        <material name="">
            <color rgba="0.250980392156863 0.250980392156863 0.250980392156863 1"/>
        </material>
        </visual>
        <collision>
        <origin rpy="0 0 0" xyz="0 0 0"/>
        <geometry>
            <mesh filename="package://rgator_model/meshes/middle_right_wheel_link.STL"/>
        </geometry>
        </collision>
    </link>
    <joint name="middle_right_wheel_joint" type="continuous">
        <origin rpy="0 0 0" xyz="-0.331320005596348 -0.61 0.0899999999999994"/>
        <parent link="base_link"/>
        <child link="middle_right_wheel_link"/>
        <axis xyz="0 1 0"/>
        <limit effort="1000" velocity="100.0"/>
    </joint>

    <!-- Rear left wheel -->
    <link name="rear_left_wheel_link">
        <inertial>
        <origin rpy="0 0 0" xyz="-1.11022302462516E-16 -0.0223230092959477 -4.44089209850063E-16"/>
        <mass value="68.0202335873534"/>
        <!-- <inertia ixx="1.8451330504804" ixy="1.11085477564446E-33" ixz="4.56370529158729E-34" iyy="2.55906848679382" iyz="1.90583886938469E-16" izz="1.8451330504804"/> -->
        <inertia ixx="0.58631238" ixy="0.0" ixz="0.0" iyy="0.33552910" iyz="0.0" izz="0.33552910"/>
        </inertial>
        <visual>
        <origin rpy="0 0 0" xyz="0 0 0"/>
        <geometry>
            <mesh filename="package://rgator_model/meshes/rear_left_wheel_link.STL"/>
        </geometry>
        <material name="">
            <color rgba="0.250980392156863 0.250980392156863 0.250980392156863 1"/>
        </material>
        </visual>
        <collision>
        <origin rpy="0 0 0" xyz="0 0 0"/>
        <geometry>
            <mesh filename="package://rgator_model/meshes/rear_left_wheel_link.STL"/>
        </geometry>
        </collision>
    </link>

    
    <joint name="rear_left_wheel_joint" type="continuous">
        <origin rpy="0 0 0" xyz="-1.02132000559635 0.61 0.0899999999999999"/>
        <parent link="base_link"/>
        <child link="rear_left_wheel_link"/>
        <axis xyz="0 1 0"/>
        <limit effort="1000" velocity="100.0"/>
    </joint>


    <!-- rear right wheel -->
    <link name="rear_right_wheel_link">
        <inertial>
        <origin rpy="0 0 0" xyz="-1.11022302462516E-16 0.0223230092959477 0"/>
        <mass value="68.0202335873534"/>
        <inertia ixx="0.58631238" ixy="0.0" ixz="0.0" iyy="0.33552910" iyz="0.0" izz="0.33552910"/>
        <!-- <inertia ixx="1.8451330504804" ixy="-2.06161374086158E-17" ixz="-8.17398264338227E-17" iyy="2.55906848679382" iyz="2.5195914990781E-16" izz="1.8451330504804"/> -->
        </inertial>
        <visual>
        <origin rpy="0 0 0" xyz="0 0 0"/>
        <geometry>
            <mesh filename="package://rgator_model/meshes/rear_right_wheel_link.STL"/>
        </geometry>
        <material name="">
            <color rgba="0.250980392156863 0.250980392156863 0.250980392156863 1"/>
        </material>
        </visual>
        <collision>
        <origin rpy="0 0 0" xyz="0 0 0"/>
        <geometry>
            <mesh filename="package://rgator_model/meshes/rear_right_wheel_link.STL"/>
        </geometry>
        </collision>
    </link>
    <joint name="rear_right_wheel_joint" type="continuous">
        <origin rpy="0 0 0" xyz="-1.02132000559635 -0.61 0.0900000000000003"/>
        <parent link="base_link"/>
        <child link="rear_right_wheel_link"/>
        <axis xyz="0 1 0"/>
        <limit effort="1000" velocity="100.0"/>
    </joint>


    <link name="top_rack_link">
        <inertial>
        <mass value="1"/>
        <origin xyz="0 0 0" rpy="0 0 0"/>
        <inertia ixx="0.0" ixy="0.0" ixz="0.0" iyy="0.0" iyz="0.0" izz="0.0"/>
        </inertial>
    </link>


    <joint name="top_rack_joint" type="fixed">
        <!-- <origin xyz="0.404 0.0 1.63" rpy="1.5708 0 3.1416" /> -->
        <origin xyz="0.367 0.0 1.58" rpy="1.5708 0 3.1416" />
        <parent link="base_link" />
        <child link="top_rack_link" />
        <axis xyz="0 0 0" />
    </joint>



    <!-- ******************************************** Transmissions ********************************************* -->


    <xacro:wheel_transmission name="rear_left_wheel" />
    <xacro:wheel_transmission name="rear_right_wheel" />

    <xacro:wheel_transmission name="front_left_wheel" />
    <xacro:wheel_transmission name="front_right_wheel" />

    <xacro:steering_hinge_transmission name="left_steering_hinge" />
    <xacro:steering_hinge_transmission name="right_steering_hinge" />

    <!-- ******************************************** Sensor ********************************************* -->

    <xacro:VLP-16 parent="top_rack_link" name="velodyne" topic="/velodyne_points" hz="10" samples="440" gpu="false">
        <origin xyz="0.0 0.0 0.0" rpy="1.5708 0 3.1416" /> <!-- 1.5708 3.1416 -->
    </xacro:VLP-16>


    <link name="front_single_camera_link">
    <collision>
      <origin xyz="0 0 0" rpy="0 0 0"/>
      <geometry>
        <box size="0.05 0.05 0.05"/>
      </geometry>
    </collision>
    <visual>
      <origin xyz="0 0 0" rpy="0 0 0"/>
      <geometry>
        <box size="0.05 0.05 0.05"/>
      </geometry>
      <!-- <material name="red"/> -->
    </visual>
    <inertial>
      <mass value="1e-5" />
      <origin xyz="0 0 0" rpy="0 0 0"/>
      <inertia ixx="1e-6" ixy="0" ixz="0" iyy="1e-6" iyz="0" izz="1e-6" />
    </inertial>
  </link>

  <!--
  <joint name="gem_front_camera_joint" type="fixed">
    <origin xyz="-0.045 0 0" rpy="-1.5708 3.1416 0"/>
    <parent link="front_camera_link"/>
    <child link="front_single_camera_link"/>
  </joint>
  -->

  <joint name="gem_front_camera_joint" type="fixed">
    <origin xyz="0.396 0 1.55" rpy="0 0 0"/>
    <parent link="base_link"/>
    <child link="front_single_camera_link"/>
  </joint>

    <!-- IMU -->
  <link name="IMU_link">

    <collision>
      <origin xyz="0 0 0" rpy="0 0 0"/>
      <geometry>
        <box size="0.1 0.1 0.1"/>
      </geometry>
    </collision>

    <visual>
      <origin xyz="0 0 0" rpy="0 0 0"/>
      <geometry>
        <box size="0.1 0.1 0.1"/>
      </geometry>
      <!-- <material name="red"/> -->
    </visual>

    <inertial>
      <origin xyz="0 0 0" rpy="0 0 0"/>
      <mass value="1"/>
      <inertia
        ixx="1.0" ixy="0.0" ixz="0.0"
        iyy="1.0" iyz="0.0"
        izz="1.0"/>
    </inertial>

  </link>

  <joint name="IMU_joint" type="fixed">
    <origin xyz="-0.246 0 0.05" rpy="0 0 -1.5708"/>
    <parent link="base_link"/>
    <child link="IMU_link"/>
  </joint>

  <!-- GPS -->
  <link name="GPS_link">
    <collision>
      <origin xyz="0 0 0" rpy="0 0 0"/>
      <geometry>
        <box size="0.1 0.1 0.1"/>
      </geometry>
    </collision>
    <visual>
      <origin xyz="0 0 0" rpy="0 0 0"/>
      <geometry>
        <box size="0.1 0.1 0.1"/>
      </geometry>
      <!-- <material name="red"/> -->
    </visual>
    <inertial>
      <origin xyz="0 0 0" rpy="0 0 0"/>
      <mass value="1"/>
      <inertia
        ixx="1.0" ixy="0.0" ixz="0.0"
        iyy="1.0" iyz="0.0"
        izz="1.0"/>
    </inertial>
  </link>


  <joint name="GPS_joint" type="fixed">
    <origin xyz="-0.246 0 0.05" rpy="0 0 0"/>
    <parent link="base_link"/>
    <child link="GPS_link"/>
  </joint>

</robot>

